[2025-10-10 12:45:13,819: INFO: data_ingestion: >>>>>> stage Data Ingestion Stage started <<<<<<]
[2025-10-10 12:45:13,840: INFO: common: yaml file: config\config.yaml loaded successfully]
[2025-10-10 12:45:13,860: INFO: common: yaml file: schema.yaml loaded successfully]
[2025-10-10 12:45:13,860: INFO: common: created directory at: artifacts]
[2025-10-10 12:45:13,860: INFO: common: created directory at: artifacts/data_ingestion]
[2025-10-10 12:45:13,860: ERROR: data_ingestion: DataIngestionConfig.__init__() got an unexpected keyword argument 'source_URL']
Traceback (most recent call last):
  File "D:\MLOPS\datascienceproject\src\datascience\pipeline\data_ingestion.py", line 24, in <module>
    obj.initiate_data_ingestion()
  File "D:\MLOPS\datascienceproject\src\datascience\pipeline\data_ingestion.py", line 15, in initiate_data_ingestion
    data_ingestion_config= config.get_data_ingestion_config()
  File "D:\MLOPS\datascienceproject\src\datascience\config\configuration.py", line 20, in get_data_ingestion_config
    data_ingestion_config=DataIngestionConfig(
TypeError: DataIngestionConfig.__init__() got an unexpected keyword argument 'source_URL'
[2025-10-10 12:50:45,751: INFO: data_ingestion: >>>>>> stage Data Ingestion Stage started <<<<<<]
[2025-10-10 12:50:45,751: INFO: common: yaml file: config\config.yaml loaded successfully]
[2025-10-10 12:50:45,768: INFO: common: yaml file: schema.yaml loaded successfully]
[2025-10-10 12:50:45,768: INFO: common: created directory at: artifacts]
[2025-10-10 12:50:45,768: INFO: common: created directory at: artifacts/data_ingestion]
[2025-10-10 12:50:45,768: ERROR: data_ingestion: DataIngestionConfig.__init__() got an unexpected keyword argument 'source_URL']
Traceback (most recent call last):
  File "D:\MLOPS\datascienceproject\src\datascience\pipeline\data_ingestion.py", line 24, in <module>
    obj.initiate_data_ingestion()
  File "D:\MLOPS\datascienceproject\src\datascience\pipeline\data_ingestion.py", line 15, in initiate_data_ingestion
    data_ingestion_config= config.get_data_ingestion_config()
  File "D:\MLOPS\datascienceproject\src\datascience\config\configuration.py", line 20, in get_data_ingestion_config
    data_ingestion_config=DataIngestionConfig(
TypeError: DataIngestionConfig.__init__() got an unexpected keyword argument 'source_URL'
[2025-10-10 12:55:22,805: INFO: data_ingestion: >>>>>> stage Data Ingestion Stage started <<<<<<]
[2025-10-10 12:55:22,805: INFO: common: yaml file: config\config.yaml loaded successfully]
[2025-10-10 12:55:22,805: INFO: common: yaml file: schema.yaml loaded successfully]
[2025-10-10 12:55:22,817: INFO: common: created directory at: artifacts]
[2025-10-10 12:55:22,818: INFO: common: created directory at: artifacts/data_ingestion]
[2025-10-10 12:55:25,551: INFO: data_ingestion: artifacts/data_ingestion/data.zip downloaded with the info:
 Connection: close
Content-Length: 23329
Cache-Control: max-age=300
Content-Security-Policy: default-src 'none'; style-src 'unsafe-inline'; sandbox
Content-Type: application/zip
ETag: "c69888a4ae59bc5a893392785a938ccd4937981c06ba8a9d6a21aa52b4ab5b6e"
Strict-Transport-Security: max-age=31536000
X-Content-Type-Options: nosniff
X-Frame-Options: deny
X-XSS-Protection: 1; mode=block
X-GitHub-Request-Id: 0F5C:34AD43:4AC97:8B8DF:68E8B4C1
Accept-Ranges: bytes
Date: Fri, 10 Oct 2025 07:25:23 GMT
Via: 1.1 varnish
X-Served-By: cache-bom-vanm7210043-BOM
X-Cache: MISS
X-Cache-Hits: 0
X-Timer: S1760081122.396538,VS0,VE1178
Vary: Authorization,Accept-Encoding
Access-Control-Allow-Origin: *
Cross-Origin-Resource-Policy: cross-origin
X-Fastly-Request-ID: fb4c584f7be8afbb2414a8f0649f9e3e2da84fa2
Expires: Fri, 10 Oct 2025 07:30:23 GMT
Source-Age: 0

]
[2025-10-10 12:55:25,573: INFO: data_ingestion: >>>>>> stage Data Ingestion Stage completed <<<<<<

x==========x]
